{
  "total_tests": 6,
  "passed": 2,
  "failed": 4,
  "success_rate": "33.3%",
  "results": [
    {
      "test": "Health Check",
      "success": false,
      "message": "Cannot connect to backend server: HTTPConnectionPool(host='localhost', port=3001): Max retries exceeded with url: /api/health (Caused by NewConnectionError('<urllib3.connection.HTTPConnection object at 0xfa25f5d13950>: Failed to establish a new connection: [Errno 111] Connection refused'))",
      "timestamp": "2025-07-10T21:04:57.780897",
      "details": {}
    },
    {
      "test": "Database Connection",
      "success": false,
      "message": "Cannot test database connection: HTTPConnectionPool(host='localhost', port=3001): Max retries exceeded with url: /api/health (Caused by NewConnectionError('<urllib3.connection.HTTPConnection object at 0xfa25f5d1cd50>: Failed to establish a new connection: [Errno 111] Connection refused'))",
      "timestamp": "2025-07-10T21:04:57.782061",
      "details": {}
    },
    {
      "test": "API Endpoints Structure",
      "success": false,
      "message": "Some API endpoints are not accessible",
      "timestamp": "2025-07-10T21:04:57.784949",
      "details": {
        "tested_endpoints": [
          "POST /patients/create",
          "GET /patients",
          "GET /health"
        ]
      }
    },
    {
      "test": "Patient Data Structure",
      "success": true,
      "message": "All required fields present in patient data structure",
      "timestamp": "2025-07-10T21:04:57.784990",
      "details": {
        "required_fields": [
          "initials",
          "firstName",
          "surname",
          "idNumber",
          "dateOfBirth",
          "maritalStatus",
          "gender",
          "phone",
          "email",
          "employerName",
          "examinationType"
        ],
        "sample_data_keys": [
          "initials",
          "firstName",
          "surname",
          "idNumber",
          "dateOfBirth",
          "maritalStatus",
          "gender",
          "phone",
          "email",
          "employerName",
          "position",
          "department",
          "employeeNumber",
          "examinationType",
          "location"
        ],
        "validation": "All required fields present"
      }
    },
    {
      "test": "SA ID Validation Logic",
      "success": true,
      "message": "SA ID 7807215422081 correctly calculates age as 46 years",
      "timestamp": "2025-07-10T21:04:57.785011",
      "details": {
        "sa_id": "7807215422081",
        "extracted_date": "1978-07-21",
        "calculated_age": 46,
        "expected_age": 46
      }
    },
    {
      "test": "Patient Creation - No Auth",
      "success": false,
      "message": "Request failed: HTTPConnectionPool(host='localhost', port=3001): Max retries exceeded with url: /api/patients/create (Caused by NewConnectionError('<urllib3.connection.HTTPConnection object at 0xfa25f5d31250>: Failed to establish a new connection: [Errno 111] Connection refused'))",
      "timestamp": "2025-07-10T21:04:57.785935",
      "details": {}
    }
  ]
}